Workbook

Sheet Inputs
A1: Parameter name | B1: Value (Central) | C1: Low Scenario Adjuster | D1: High Scenario Adjuster
A2: PremiumGrowthUCC | B2: 0.045 | C2: =(0.85*B2) -> 0.03825 | D2: =(1.15*B2) -> 0.05175
A3: IncomeGrowth | B3: 0.035 | C3: =(0.85*B3) -> 0.02975 | D3: =(1.15*B3) -> 0.04025
A4: Alpha (α) | B4: 0.5 | C4: =(0.85*B4) -> 0.425 | D4: =(1.15*B4) -> 0.575
A5: Beta_max (β_max) | B5: 0.35 | C5: =(0.85*B5) -> 0.2975 | D5: =(1.15*B5) -> 0.4025
A6: z_L | B6: 1.5 | C6: =(0.85*B6) -> 1.275 | D6: =(1.15*B6) -> 1.725
A7: z_U | B7: 4 | C7: =(0.85*B7) -> 3.4 | D7: =(1.15*B7) -> 4.6
A8: Kappa (κ) | B8: 0.9 | C8: =(0.85*B8) -> 0.765 | D8: =(1.15*B8) -> 1.035
A9: Phi (φ) | B9: 0.1 | C9: =(0.85*B9) -> 0.085 | D9: =(1.15*B9) -> 0.115
A10: Gamma_max (γ_max) | B10: 800 | C10: =(0.85*B10) -> 680 | D10: =(1.15*B10) -> 920
A11: zL_prime | B11: 2 | C11: =(0.85*B11) -> 1.7 | D11: =(1.15*B11) -> 2.3
A12: zU_prime | B12: 5 | C12: =(0.85*B12) -> 4.25 | D12: =(1.15*B12) -> 5.75
A13: H_adult | B13: 750 | C13: =(0.85*B13) -> 637.5 | D13: =(1.15*B13) -> 862.5
... A24: Enrollment Growth | B24: 0.008 | C24: =(0.85*B24) -> 0.0068 | D24: =(1.15*B24) -> 0.0092
A25: TotalPopulation_2025 | B25: =B20 + B21 + B22 -> 274000000 | C25: =(0.85*B25) -> 232900000 | D25: =(1.15*B25) -> 315100000
A30: ACA_PTC_2025 | B30: 70 | C30: =(0.85*B30) -> 59.5 | D30: =(1.15*B30) -> 80.5
A31: ACA_CSR_2025 | B31: 12 | C31: =(0.85*B31) -> 10.2 | D31: =(1.15*B31) -> 13.8
A32: MedicaidExpansion_2025 | B32: 98 | C32: =(0.85*B32) -> 83.3 | D32: =(1.15*B32) -> 112.7
A33: MarketplaceAdmin_2025 | B33: 3 | C33: =(0.85*B33) -> 2.55 | D33: =(1.15*B33) -> 3.45
A34: ExclusionRevenue_2025 | B34: 22 | C34: =(0.85*B34) -> 18.7 | D34: =(1.15*B34) -> 25.3
A40: BenchmarkPremium_2025 | B40: 7500 | C40: =(0.85*B40) -> 6375 | D40: =(1.15*B40) -> 8625
A41: MedianIncome_2025 | B41: 71000 | C41: =(0.85*B41) -> 60350 | D41: =(1.15*B41) -> 81650
A44: MedicaidNonExpansion_2025 | B44: 400 | C44: =(B44*0.85) -> 340 | D44: =(B44*1.15) -> 460
A45: UncompensatedCare_2025 | B45: 50 | C45: =(B45*0.85) -> 42.5 | D45: =(B45*1.15) -> 57.5
A46: EmployerExclusionFull_2025 | B46: 350 | C46: =(B46*0.85) -> 297.5 | D46: =(B46*1.15) -> 402.5
A50: w1 (premium weight) | B50: 0.5 | C50: =(0.85*B50) -> 0.425 | D50: =(1.15*B50) -> 0.575
A51: w2 (income weight) | B51: 0.5 | C51: =(0.85*B51) -> 0.425 | D51: =(1.15*B51) -> 0.575
A53: ReinsuranceShare | B53: 0.05
A54: TransAdmin_2026 | B54: 4
A55: TransAdmin_2027 | B55: 3
A56: TransAdmin_2028 | B56: 2
A58: SilverLoading_2025 | B58: 3.1 | C58: =B58*0.85 -> 2.635 | D58: =B58*1.15 -> 3.565
A59: 1332PassThrough_2025 | B59: 5 | C59: =B59*0.85 -> 4.25 | D59: =B59*1.15 -> 5.75
A60: ACARiskAdj_Admin_2025 | B60: 0.05 | C60: =B60*0.85 -> 0.0425 | D60: =B60*1.15 -> 0.0575
A61: MedicaidChurn_Admin_2025 | B61: 3 | C61: =B61*0.85 -> 2.55 | D61: =B61*1.15 -> 3.45
A63: Avoidable_ED_Cost_2026 | B63: 42000000000 | C63: =B63*0.85 -> 35700000000 | D63: =B63*1.15 -> 48300000000
A64: Reduction_Rate | B64: 0.1 | C64: =B64*0.85 -> 0.085 | D64: =B64*1.15 -> 0.115
A65: Federal_Share | B65: 0.45 | C65: =B65*0.85 -> 0.3825 | D65: =B65*1.15 -> 0.5175
A67: AvoidedEROverutilization_2026 | B67: 2 | C67: 1 | D67: 3
A68: BadDebtReduction_2026 (%) | B68: 0.25 | C68: 0.15 | D68: 0.35
...

Sheet BetaCalc
A1: Band | B1: z (normalized income) | C1: PopShare | D1: FPL% | E1: rough average income | F1: β(z)
A2: Low income | B2: 1.2 | C2: 0.3 | D2: <150 | E2: ≲$35–40k | F2: =IF($B2<=Inputs!$B$6,Inputs!$B$5,IF($B2>=Inputs!$B$7,0,Inputs!$B$5*(1-Inputs!$B$8*POWER(($B2-Inputs!$B$6)/(Inputs!$B$7-Inputs!$B$6),Inputs!$B$9)))) -> 0.35
A3: Lower-middle | B3: 2.2 | C3: 0.3 | D3: 150-300 | E3: $35–70k | F3: =IF($B3<=Inputs!$B$6,Inputs!$B$5,IF($B3>=Inputs!$B$7,0,Inputs!$B$5*(1-Inputs!$B$8*POWER(($B3-Inputs!$B$6)/(Inputs!$B$7-Inputs!$B$6),Inputs!$B$9)))) -> 0.072651158
A4: Upper-middle | B4: 3.2 | C4: 0.25 | D4: 300-600 | E4: $70–140k | F4: =IF($B4<=Inputs!$B$6,Inputs!$B$5,IF($B4>=Inputs!$B$7,0,Inputs!$B$5*(1-Inputs!$B$8*POWER(($B4-Inputs!$B$6)/(Inputs!$B$7-Inputs!$B$6),Inputs!$B$9)))) -> 0.046917092
A5: High income | B5: 4.5 | C5: 0.15 | D5: >600 | E5: > $140k | F5: =IF($B5<=Inputs!$B$6,Inputs!$B$5,IF($B5>=Inputs!$B$7,0,Inputs!$B$5*(1-Inputs!$B$8*POWER(($B5-Inputs!$B$6)/(Inputs!$B$7-Inputs!$B$6),Inputs!$B$9)))) -> 0
A10: Average Beta | B10: =SUMPRODUCT(C2:C5, F2:F5) -> 0.13852462
A11: Average Federal Share | B11: =Inputs!$B$4 + B10 -> 0.63852462

Sheet GammaCalc 
A1: Band | B1: z (normalized income) | C1: PopShare | D1: FPL% | E1: rough average income | F1: γ(z)
A2: Low income | B2: 1.2 | C2: 0.3 | D2: <150 | E2: ≲$35–40k | F2: =IF($B2<=Inputs!$B$11,Inputs!$B$10,IF($B2>=Inputs!$B$12,0,Inputs!$B$10*(1-($B2-Inputs!$B$11)/(Inputs!$B$12-Inputs!$B$11)))) -> 800
A3: Lower-middle | B3: 2.2 | C3: 0.3 | D3: 150-300 | E3: $35–70k | F3: =IF($B3<=Inputs!$B$11,Inputs!$B$10,IF($B3>=Inputs!$B$12,0,Inputs!$B$10*(1-($B3-Inputs!$B$11)/(Inputs!$B$12-Inputs!$B$11)))) -> 746.66667
A4: Upper-middle | B4: 3.2 | C4: 0.25 | D4: 300-600 | E4: $70–140k | F4: =IF($B4<=Inputs!$B$11,Inputs!$B$10,IF($B4>=Inputs!$B$12,0,Inputs!$B$10*(1-($B4-Inputs!$B$11)/(Inputs!$B$12-Inputs!$B$11)))) -> 480
A5: High income | B5: 4.5 | C5: 0.15 | D5: >600 | E5: > $140k | F5: 0
A7: Average Gamma | B7: =SUMPRODUCT($C$2:$C$5,$F$2:$F$5) -> 584

Sheet Outlays
A1: all done with central range estimation | B1: 2026 | C1: 2027 | D1: 2028 | E1: 2029 | F1: 2030 | G1: 2031 | H1: 2032 | I1: 2033 | J1: 2034 | K1: 2035
A3: Benchmark Premium (per enrollee) | B3: =Inputs!$B$40 -> 7500 | C3: =B3*(1+Inputs!$B$2) -> 7837.5 | D3: =C3*(1+Inputs!$B$2) -> 8190.1875 | E3: =D3*(1+Inputs!$B$2) -> 8558.7459 | F3: =E3*(1+Inputs!$B$2) -> 8943.8895 | G3: =F3*(1+Inputs!$B$2) -> 9346.3645 | H3: =G3*(1+Inputs!$B$2) -> 9766.9509 | I3: =H3*(1+Inputs!$B$2) -> 10206.464 | J3: =I3*(1+Inputs!$B$2) -> 10665.755 | K3: =J3*(1+Inputs!$B$2) -> 11145.714
A4: Enrollees (persons) | B4: =Inputs!$B$20-Inputs!$B$106 -> 128900000 | C4: =B4*(1+Inputs!$B$24) -> 129931200 | D4: =C4*(1+Inputs!$B$24) -> 1.3097065e+08 | E4: =D4*(1+Inputs!$B$24) -> 1.3201841e+08 | F4: =E4*(1+Inputs!$B$24) -> 1.3307456e+08 | G4: =F4*(1+Inputs!$B$24) -> 1.3413916e+08 | H4: =G4*(1+Inputs!$B$24) -> 1.3521227e+08 | I4: =H4*(1+Inputs!$B$24) -> 1.3629397e+08 | J4: =I4*(1+Inputs!$B$24) -> 1.3738432e+08 | K4: =J4*(1+Inputs!$B$24) -> 1.384834e+08
A5: Total Benchmark Premium Volume (billions) | B5: =B3 * B4 / 1000000000 -> 966.75 | C5: =C3 * C4 / 1000000000 -> 1018.3358 | D5: =D3 * D4 / 1000000000 -> 1072.6742 | E5: =E3 * E4 / 1000000000 -> 1129.9121 | F5: =F3 * F4 / 1000000000 -> 1190.2042 | G5: =G3 * G4 / 1000000000 -> 1253.7135 | H5: =H3 * H4 / 1000000000 -> 1320.6116 | I5: =I3 * I4 / 1000000000 -> 1391.0795 | ... K5: =K3 * K4 / 1000000000 -> 1543.4963
A7: Average Federal Share of Catastrophic Premium (α + β weighted) | B7: =BetaCalc!$B$11 -> 0.63852462 | C7: =BetaCalc!$B$11 -> 0.63852462 | D7: =BetaCalc!$B$11 -> 0.63852462 | E7: =BetaCalc!$B$11 -> 0.63852462 | F7: =BetaCalc!$B$11 -> 0.63852462 | G7: =BetaCalc!$B$11 -> 0.63852462 | H7: =BetaCalc!$B$11 -> 0.63852462 | I7: =BetaCalc!$B$11 -> 0.63852462 | ... K7: =BetaCalc!$B$11 -> 0.63852462
A8: Catastrophic Credits (billions) | B8: =B7*B5 -> 617.29368 | C8: =C7*C5 -> 650.23247 | D8: =D7*D5 -> 684.92887 | E8: =E7*E5 -> 721.47668 | F8: =F7*F5 -> 759.97467 | G8: =G7*G5 -> 800.52692 | H8: =H7*H5 -> 843.24304 | I8: =I7*I5 -> 888.23849 | ... K8: =K7*K5 -> 985.56037
A10: Adult HSA Deposits (billions) | B10: =(Inputs!B20-Inputs!B106)*(Inputs!B13+'GammaCalc '!B7)/1000000000 -> 171.9526 | C10: =B10 * (1 + (Inputs!B2*Inputs!B50 + Inputs!B3*Inputs!B51)) -> 178.8307 | D10: =C10 * (1 + (Inputs!B2*Inputs!B50 + Inputs!B3*Inputs!B51)) -> 185.98393 | E10: =D10 * (1 + (Inputs!B2*Inputs!B50 + Inputs!B3*Inputs!B51)) -> 193.42329 | F10: =E10 * (1 + (Inputs!B2*Inputs!B50 + Inputs!B3*Inputs!B51)) -> 201.16022 | G10: =F10 * (1 + (Inputs!B2*Inputs!B50 + Inputs!B3*Inputs!B51)) -> 209.20663 | H10: =G10 * (1 + (Inputs!B2*Inputs!B50 + Inputs!B3*Inputs!B51)) -> 217.5749 | I10: =H10 * (1 + (Inputs!B2*Inputs!B50 + Inputs!B3*Inputs!B51)) -> 226.27789 | J10: =I10 * (1 + (Inputs!B2*Inputs!B50 + Inputs!B3*Inputs!B51)) -> 235.32901 | K10: =J10 * (1 + (Inputs!B2*Inputs!B50 + Inputs!B3*Inputs!B51)) -> 244.74217
A11: Child 0–5 HSA Deposits (billions) | B11: =Inputs!B21*(Inputs!B14+'GammaCalc '!B7)/1000000000 -> 45.216 | C11: =B11 * (1 + (Inputs!B2*Inputs!B50 + Inputs!B3*Inputs!B51)) -> 47.02464 | D11: =C11 * (1 + (Inputs!B2*Inputs!B50 + Inputs!B3*Inputs!B51)) -> 48.905626 | E11: =D11 * (1 + (Inputs!B2*Inputs!B50 + Inputs!B3*Inputs!B51)) -> 50.861851 | F11: =E11 * (1 + (Inputs!B2*Inputs!B50 + Inputs!B3*Inputs!B51)) -> 52.896325 | G11: =F11 * (1 + (Inputs!B2*Inputs!B50 + Inputs!B3*Inputs!B51)) -> 55.012178 | H11: =G11 * (1 + (Inputs!B2*Inputs!B50 + Inputs!B3*Inputs!B51)) -> 57.212665 | I11: =H11 * (1 + (Inputs!B2*Inputs!B50 + Inputs!B3*Inputs!B51)) -> 59.501171 | J11: =I11 * (1 + (Inputs!B2*Inputs!B50 + Inputs!B3*Inputs!B51)) -> 61.881218 | K11: =J11 * (1 + (Inputs!B2*Inputs!B50 + Inputs!B3*Inputs!B51)) -> 64.356467
A12: Child 6–17 HSA Deposits (billions) | B12: =Inputs!B22*(Inputs!B15+'GammaCalc '!B7)/1000000000 -> 79.2 | C12: =B12 * (1 + (Inputs!B2*Inputs!B50 + Inputs!B3*Inputs!B51)) -> 82.368 | D12: =C12 * (1 + (Inputs!B2*Inputs!B50 + Inputs!B3*Inputs!B51)) -> 85.66272 | E12: =D12 * (1 + (Inputs!B2*Inputs!B50 + Inputs!B3*Inputs!B51)) -> 89.089229 | F12: =E12 * (1 + (Inputs!B2*Inputs!B50 + Inputs!B3*Inputs!B51)) -> 92.652798 | G12: =F12 * (1 + (Inputs!B2*Inputs!B50 + Inputs!B3*Inputs!B51)) -> 96.35891 | H12: =G12 * (1 + (Inputs!B2*Inputs!B50 + Inputs!B3*Inputs!B51)) -> 100.21327 | I12: =H12 * (1 + (Inputs!B2*Inputs!B50 + Inputs!B3*Inputs!B51)) -> 104.2218 | J12: =I12 * (1 + (Inputs!B2*Inputs!B50 + Inputs!B3*Inputs!B51)) -> 108.39067 | K12: =J12 * (1 + (Inputs!B2*Inputs!B50 + Inputs!B3*Inputs!B51)) -> 112.7263
A13: Chronic Condition Supplements (billions) | B13: =Inputs!$B$16 * Inputs!$B$25 * Inputs!$B$23 / 1000000000 -> 54.8 | C13: =B13 * (1 + (Inputs!B2*Inputs!B50 + Inputs!B3*Inputs!B51)) -> 56.992 | D13: =C13 * (1 + (Inputs!B2*Inputs!B50 + Inputs!B3*Inputs!B51)) -> 59.27168 | E13: =D13 * (1 + (Inputs!B2*Inputs!B50 + Inputs!B3*Inputs!B51)) -> 61.642547 | F13: =E13 * (1 + (Inputs!B2*Inputs!B50 + Inputs!B3*Inputs!B51)) -> 64.108249 | G13: =F13 * (1 + (Inputs!B2*Inputs!B50 + Inputs!B3*Inputs!B51)) -> 66.672579 | H13: =G13 * (1 + (Inputs!B2*Inputs!B50 + Inputs!B3*Inputs!B51)) -> 69.339482 | I13: =H13 * (1 + (Inputs!B2*Inputs!B50 + Inputs!B3*Inputs!B51)) -> 72.113062 | J13: =I13 * (1 + (Inputs!B2*Inputs!B50 + Inputs!B3*Inputs!B51)) -> 74.997584 | K13: =J13 * (1 + (Inputs!B2*Inputs!B50 + Inputs!B3*Inputs!B51)) -> 77.997487
A14: Total Federal HSA Deposits (billions) | B14: =SUM(B10:B13) -> 351.1686 | C14: =SUM(C10:C13) -> 365.21534 | D14: =SUM(D10:D13) -> 379.82396 | E14: =SUM(E10:E13) -> 395.01692 | F14: =SUM(F10:F13) -> 410.81759 | G14: =SUM(G10:G13) -> 427.2503 | H14: =SUM(H10:H13) -> 444.34031 | I14: =SUM(I10:I13) -> 462.11392 | ... K14: =SUM(K10:K13) -> 499.82242
A16: Federal Reinsurance (billions) | B16: =Inputs!$B$53 * B5 * (Inputs!$B$84 / Inputs!$B$83) -> 26.182813 | C16: =Inputs!$B$53 * C5 * (Inputs!$B$84 / Inputs!$B$83) -> 27.579927 | D16: =Inputs!$B$53 * D5 * (Inputs!$B$84 / Inputs!$B$83) -> 29.051592 | E16: =Inputs!$B$53 * E5 * (Inputs!$B$84 / Inputs!$B$83) -> 30.601785 | F16: =Inputs!$B$53 * F5 * (Inputs!$B$84 / Inputs!$B$83) -> 32.234697 | G16: =Inputs!$B$53 * G5 * (Inputs!$B$84 / Inputs!$B$83) -> 33.95474 | H16: =Inputs!$B$53 * H5 * (Inputs!$B$84 / Inputs!$B$83) -> 35.766565 | I16: =Inputs!$B$53 * I5 * (Inputs!$B$84 / Inputs!$B$83) -> 37.675069 | ... K16: =Inputs!$B$53 * K5 * (Inputs!$B$84 / Inputs!$B$83) -> 41.803024
A18: Transition/Admin Costs (billions) | B18: =Inputs!$B$54 -> 4 | C18: =Inputs!$B$55 -> 3 | D18: =Inputs!$B$56 -> 2 | E18: 0 | F18: 0 | G18: 0 | H18: 0 | I18: 0 | J18: 0 | K18: 0
A20: Total Federal Outlays (sum of all above) | B20: =B8 + B14 + B16 + B18 -> 998.64509 | C20: =C8 + C14 + C16 + C18 -> 1046.0277 | D20: =D8 + D14 + D16 + D18 -> 1095.8044 | E20: =E8 + E14 + E16 + E18 -> 1147.0954 | F20: =F8 + F14 + F16 + F18 -> 1203.027 | G20: =G8 + G14 + G16 + G18 -> 1261.732 | H20: =H8 + H14 + H16 + H18 -> 1323.3499 | I20: =I8 + I14 + I16 + I18 -> 1388.0275 | ... K20: =K8 + K14 + K16 + K18 -> 1527.1858

Sheet Savings
B1: 2026 | C1: 2027 | D1: 2028 | E1: 2029 | F1: 2030 | G1: 2031 | H1: 2032 | I1: 2033 | J1: 2034 | K1: 2035
A3: ACA Premium Tax Credits (baseline) (billions) Baseline (CBO Pub. 59273 Table A-2; 2026–2033), extrapolated thereafter | B3: 82 | C3: 82 | D3: 85 | E3: 90 | F3: 93 | G3: 96 | H3: 102 | I3: 109 | J3: =I3*(1+Inputs!$B$17) -> 115.54 | K3: =J3*(1+Inputs!$B$17) -> 122.4724
A4: ACA CSR Payments (billions) | B4: =Inputs!$B$31*(1+Inputs!$B$17) -> 12.72 | C4: =B4*(1+Inputs!$B$17) -> 13.4832 | D4: =C4*(1+Inputs!$B$17) -> 14.292192 | E4: =D4*(1+Inputs!$B$17) -> 15.149724 | F4: =E4*(1+Inputs!$B$17) -> 16.058707 | G4: =F4*(1+Inputs!$B$17) -> 17.022229 | H4: =G4*(1+Inputs!$B$17) -> 18.043563 | I4: =H4*(1+Inputs!$B$17) -> 19.126177 | J4: =I4*(1+Inputs!$B$17) -> 20.273748 | K4: =J4*(1+Inputs!$B$17) -> 21.490172
A5: Medicaid Expansion Adults baseline (federal share) (billions) Baseline (CBO Pub. 59273 Table A-2; 2026–2033), extrapolated thereafter | B5: 120 | C5: 129 | D5: 138 | E5: 149 | F5: 159 | G5: 171 | H5: 184 | I5: 198 | J5: =I5*(1+Inputs!$B$17) -> 209.88 | K5: =J5*(1+Inputs!$B$17) -> 222.4728
A6: Marketplace Admin / Plan Management (billions) | B6: =Inputs!$B$33*(1+Inputs!$B$17) -> 3.18 | C6: =B6*(1+Inputs!$B$17) -> 3.3708 | D6: =C6*(1+Inputs!$B$17) -> 3.573048 | E6: =D6*(1+Inputs!$B$17) -> 3.7874309 | F6: =E6*(1+Inputs!$B$17) -> 4.0146767 | G6: =F6*(1+Inputs!$B$17) -> 4.2555573 | H6: =G6*(1+Inputs!$B$17) -> 4.5108908 | I6: =H6*(1+Inputs!$B$17) -> 4.7815442 | J6: =I6*(1+Inputs!$B$17) -> 5.0684369 | K6: =J6*(1+Inputs!$B$17) -> 5.3725431
A7: Employer Exclusion Revenue Loss (under current law) (billions) Baseline (CBO Pub. 59273 Table A-2; 2026–2033), extrapolated thereafter | B7: 451 | C7: 495 | D7: 523 | E7: 550 | F7: 578 | G7: 608 | H7: 641 | I7: 676 | J7: =I7*(1+Inputs!$B$17) -> 716.56 | K7: =J7*(1+Inputs!$B$17) -> 759.5536
A8: Medicaid NON-expansion baseline (2026) (billions) | B8: =Inputs!$B$44 * (1 + Inputs!$B$17) -> 424 | C8: =B8*(1+Inputs!$B$17) -> 449.44 | D8: =C8*(1+Inputs!$B$17) -> 476.4064 | E8: =D8*(1+Inputs!$B$17) -> 504.99078 | F8: =E8*(1+Inputs!$B$17) -> 535.29023 | G8: =F8*(1+Inputs!$B$17) -> 567.40764 | H8: =G8*(1+Inputs!$B$17) -> 601.4521 | I8: =H8*(1+Inputs!$B$17) -> 637.53923 | J8: =I8*(1+Inputs!$B$17) -> 675.79158 | K8: =J8*(1+Inputs!$B$17) -> 716.33908
A9: Uncompensated care baseline (2026) (billions) | B9: =Inputs!$B$45 * (1 + Inputs!$B$17) -> 53 | C9: =B9*(1+Inputs!$B$17) -> 56.18 | D9: =C9*(1+Inputs!$B$17) -> 59.5508 | E9: =D9*(1+Inputs!$B$17) -> 63.123848 | F9: =E9*(1+Inputs!$B$17) -> 66.911279 | G9: =F9*(1+Inputs!$B$17) -> 70.925956 | H9: =G9*(1+Inputs!$B$17) -> 75.181513 | I9: =H9*(1+Inputs!$B$17) -> 79.692404 | J9: =I9*(1+Inputs!$B$17) -> 84.473948 | K9: =J9*(1+Inputs!$B$17) -> 89.542385
A10: FULL employer exclusion baseline (2026) (billions) | B10: =Inputs!$B$46 * (1 + Inputs!$B$17) -> 371 | C10: =B10*(1+Inputs!$B$17) -> 393.26 | D10: =C10*(1+Inputs!$B$17) -> 416.8556 | E10: =D10*(1+Inputs!$B$17) -> 441.86694 | F10: =E10*(1+Inputs!$B$17) -> 468.37895 | G10: =F10*(1+Inputs!$B$17) -> 496.48169 | H10: =G10*(1+Inputs!$B$17) -> 526.27059 | I10: =H10*(1+Inputs!$B$17) -> 557.84683 | J10: =I10*(1+Inputs!$B$17) -> 591.31764 | K10: =J10*(1+Inputs!$B$17) -> 626.79669
A11: SilverLoading (billions) | B11: =Inputs!B58 * (1 + Inputs!B17) -> 3.286 | C11: =B11* (1 + Inputs!B17) -> 3.48316 | D11: =C11* (1 + Inputs!B17) -> 3.6921496 | E11: =D11* (1 + Inputs!B17) -> 3.9136786 | F11: =E11* (1 + Inputs!B17) -> 4.1484993 | G11: =F11* (1 + Inputs!B17) -> 4.3974092 | H11: =G11* (1 + Inputs!B17) -> 4.6612538 | I11: =H11* (1 + Inputs!B17) -> 4.940929 | J11: =I11* (1 + Inputs!B17) -> 5.2373848 | K11: =J11* (1 + Inputs!B17) -> 5.5516279
A12: 1332PassThrough (billions) | B12: =Inputs!B59 * (1+ Inputs!B17) -> 5.3 | C12: =B12 * (1 + Inputs!B17) -> 5.618 | D12: =C12 * (1 + Inputs!B17) -> 5.95508 | E12: =D12 * (1 + Inputs!B17) -> 6.3123848 | F12: =E12 * (1 + Inputs!B17) -> 6.6911279 | G12: =F12 * (1 + Inputs!B17) -> 7.0925956 | H12: =G12 * (1 + Inputs!B17) -> 7.5181513 | I12: =H12 * (1 + Inputs!B17) -> 7.9692404 | J12: =I12 * (1 + Inputs!B17) -> 8.4473948 | K12: =J12 * (1 + Inputs!B17) -> 8.9542385
A13: ACARiskAdj_Admin (billions) | B13: =(Inputs!B60*(1+Inputs!B17)) -> 0.053 | C13: =B13* (1 + Inputs!B17) -> 0.05618 | D13: =C13* (1 + Inputs!B17) -> 0.0595508 | E13: =D13* (1 + Inputs!B17) -> 0.063123848 | F13: =E13* (1 + Inputs!B17) -> 0.066911279 | G13: =F13* (1 + Inputs!B17) -> 0.070925956 | H13: =G13* (1 + Inputs!B17) -> 0.075181513 | I13: =H13* (1 + Inputs!B17) -> 0.079692404 | J13: =I13* (1 + Inputs!B17) -> 0.084473948 | K13: =J13* (1 + Inputs!B17) -> 0.089542385
A14: MedicaidChurn_Admin (billions) | B14: =(Inputs!B61*(1+Inputs!B17)) -> 3.18 | C14: =B14 *(1 + Inputs!B17) -> 3.3708 | D14: =C14 *(1 + Inputs!B17) -> 3.573048 | E14: =D14 *(1 + Inputs!B17) -> 3.7874309 | F14: =E14 *(1 + Inputs!B17) -> 4.0146767 | G14: =F14 *(1 + Inputs!B17) -> 4.2555573 | H14: =G14 *(1 + Inputs!G17) -> 4.2555573 | I14: =H14 *(1 + Inputs!H17) -> 4.2555573 | J14: =I14 *(1 + Inputs!I17) -> 4.2555573 | K14: =J14 *(1 + Inputs!J17) -> 4.2555573
A15: Avoided ER Overutilization (billions) | B15: =Inputs!B67 -> 2 | C15: =B15*1.06 -> 2.12 | D15: =C15*1.06 -> 2.2472 | E15: =D15*1.06 -> 2.382032 | F15: =E15*1.06 -> 2.5249539 | G15: =F15*1.06 -> 2.6764512 | H15: =G15*1.06 -> 2.8370382 | I15: =H15*1.06 -> 3.0072605 | J15: =I15*1.06 -> 3.1876961 | K15: =J15*1.06 -> 3.3789579
A16: BadDebtReduction effect (billions) | B16: =$B$9* Inputs!B68*Inputs!B65 -> 5.9625 | C16: =B16*1.06 -> 6.32025 | D16: =C16*1.06 -> 6.699465 | E16: =D16*1.06 -> 7.1014329 | F16: =E16*1.06 -> 7.5275189 | G16: =F16*1.06 -> 7.97917 | H16: =G16*1.06 -> 8.4579202 | I16: =H16*1.06 -> 8.9653954 | J16: =I16*1.06 -> 9.5033191 | K16: =J16*1.06 -> 10.073518
A17: CharityCareTaxOffset (billions) | B17: =Inputs!B69 -> 2 | C17: =B17*1.06 -> 2.12 | D17: =C17*1.06 -> 2.2472 | E17: =D17*1.06 -> 2.382032 | F17: =E17*1.06 -> 2.5249539 | G17: =F17*1.06 -> 2.6764512 | H17: =G17*1.06 -> 2.8370382 | I17: =H17*1.06 -> 3.0072605 | J17: =I17*1.06 -> 3.1876961 | K17: =J17*1.06 -> 3.3789579
A18: PreventiveCareOffset (billions) | B18: =Inputs!B74 -> 1.5 | C18: =B18*1.06 -> 1.59 | D18: =C18*1.06 -> 1.6854 | E18: =D18*1.06 -> 1.786524 | F18: =E18*1.06 -> 1.8937154 | G18: =F18*1.06 -> 2.0073384 | H18: =G18*1.06 -> 2.1277787 | I18: =H18*1.06 -> 2.2554454 | J18: =I18*1.06 -> 2.3907721 | K18: =J18*1.06 -> 2.5342184
A19: EndOfLifeIntensitySavings (billions) | B19: =Inputs!B75 -> 2 | C19: =B19*1.06 -> 2.12 | D19: =C19*1.06 -> 2.2472 | E19: =D19*1.06 -> 2.382032 | F19: =E19*1.06 -> 2.5249539 | G19: =F19*1.06 -> 2.6764512 | H19: =G19*1.06 -> 2.8370382 | I19: =H19*1.06 -> 3.0072605 | J19: =I19*1.06 -> 3.1876961 | K19: =J19*1.06 -> 3.3789579
A20: MedicationAdherenceSavings (billions) | B20: =Inputs!B76 -> 0.25 | C20: =B20*1.06 -> 0.265 | D20: =C20*1.06 -> 0.2809 | E20: =D20*1.06 -> 0.297754 | F20: =E20*1.06 -> 0.31561924 | G20: =F20*1.06 -> 0.33455639 | H20: =G20*1.06 -> 0.35462978 | I20: =H20*1.06 -> 0.37590756 | J20: =I20*1.06 -> 0.39846202 | K20: =J20*1.06 -> 0.42236974
A21: DiagnosticDuplicationSavings (billions) | B21: =Inputs!B77 -> 0.25 | C21: =B21*1.06 -> 0.265 | D21: =C21*1.06 -> 0.2809 | E21: =D21*1.06 -> 0.297754 | F21: =E21*1.06 -> 0.31561924 | G21: =F21*1.06 -> 0.33455639 | H21: =G21*1.06 -> 0.35462978 | I21: =H21*1.06 -> 0.37590756 | J21: =I21*1.06 -> 0.39846202 | K21: =J21*1.06 -> 0.42236974
A22: TaxableWageIncrease (billions) | B22: 0 | C22: 0 | D22: 0 | E22: 0 | F22: 0 | G22: 0 | H22: 0 | I22: 0 | J22: 0 | K22: 0
A23: Disability (billions) | B23: 0 | C23: 0 | D23: 0 | E23: 0 | F23: 0 | G23: 0 | H23: 0 | I23: 0 | J23: 0 | K23: 0
A24: Behavioral Savings (billions) aggregate | B24: =SUM(B16:B23) -> 11.9625 | C24: =SUM(C16:C23) -> 12.68025 | D24: =SUM(D16:D23) -> 13.441065 | E24: =SUM(E16:E23) -> 14.247529 | F24: =SUM(F16:F23) -> 15.102381 | G24: =SUM(G16:G23) -> 16.008523 | H24: =SUM(H16:H23) -> 16.969035 | I24: =SUM(I16:I23) -> 17.987177 | ... K24: =SUM(K16:K23) -> 20.210392
A28: Savings: PTC Eliminated (billions) | B28: =B3 -> 82 | C28: =C3 -> 82 | D28: =D3 -> 85 | E28: =E3 -> 90 | F28: =F3 -> 93 | G28: =G3 -> 96 | H28: =H3 -> 102 | I28: =I3 -> 109 | ... K28: =K3 -> 122.4724
A29: Savings: CSR Eliminated (billions) | B29: =B4 -> 12.72 | C29: =C4 -> 13.4832 | D29: =D4 -> 14.292192 | E29: =E4 -> 15.149724 | F29: =F4 -> 16.058707 | G29: =G4 -> 17.022229 | H29: =H4 -> 18.043563 | I29: =I4 -> 19.126177 | ... K29: =K4 -> 21.490172
A30: Savings: Medicaid Expansion Transition (billions) | B30: =B5 -> 120 | C30: =0.67*C5 -> 86.43 | D30: =0.33*D5 -> 45.54 | E30: 0 | F30: 0 | G30: 0 | H30: 0 | I30: 0 | J30: 0 | K30: 0
A31: Savings: Marketplace Admin Eliminated (billions) | B31: =B6 -> 3.18 | C31: =C6 -> 3.3708 | D31: =D6 -> 3.573048 | E31: =E6 -> 3.7874309 | F31: =F6 -> 4.0146767 | G31: =G6 -> 4.2555573 | H31: =H6 -> 4.5108908 | I31: =I6 -> 4.7815442 | ... K31: =K6 -> 5.3725431
A32: Revenue Gain: Employer Exclusion Phase-Down (billions) | B32: =0.1*B7 -> 45.1 | C32: =0.2*C7 -> 99 | D32: =0.3*D7 -> 156.9 | E32: =0.4*E7 -> 220 | F32: =0.5*F7 -> 289 | G32: =0.6*G7 -> 364.8 | H32: =0.7*H7 -> 448.7 | I32: =0.8*I7 -> 540.8 | J32: =0.9*J7 -> 644.904 | K32: =1*K7 -> 759.5536
A33: Savings: Medicaid Non-Expansion Adults Transition | B33: =B8 -> 424 | C33: =C8*0.8 -> 359.552 | D33: =D8*0.6 -> 285.84384 | E33: =E8*0.4 -> 201.99631 | F33: =F8*0.2 -> 107.05805 | G33: 0 | H33: 0 | I33: 0 | J33: 0 | K33: 0
A34: Savings: Uncompensated Care Reduction (billions) | B34: =0.8*B9 -> 42.4 | C34: =0.8*C9 -> 44.944 | D34: =0.8*D9 -> 47.64064 | E34: =0.8*E9 -> 50.499078 | F34: =0.8*F9 -> 53.529023 | G34: =0.8*G9 -> 56.740764 | H34: =0.8*H9 -> 60.14521 | I34: =0.8*I9 -> 63.753923 | ... K34: =0.8*K9 -> 71.633908
A35: Savings:SilverLoading (billions) | B35: =B11 -> 3.286 | C35: =C11 -> 3.48316 | D35: =D11 -> 3.6921496 | E35: =E11 -> 3.9136786 | F35: =F11 -> 4.1484993 | G35: =G11 -> 4.3974092 | H35: =H11 -> 4.6612538 | I35: =I11 -> 4.940929 | ... K35: =K11 -> 5.5516279
A36: Savings: 1332PassThrough (billions) | B36: =B12 -> 5.3 | C36: =C12 -> 5.618 | D36: =D12 -> 5.95508 | E36: =E12 -> 6.3123848 | F36: =F12 -> 6.6911279 | G36: =G12 -> 7.0925956 | H36: =H12 -> 7.5181513 | I36: =I12 -> 7.9692404 | ... K36: =K12 -> 8.9542385
A37: Savings: ACARiskAdj_Admin (billions) | B37: =B13 -> 0.053 | C37: =C13 -> 0.05618 | D37: =D13 -> 0.0595508 | E37: =E13 -> 0.063123848 | F37: =F13 -> 0.066911279 | G37: =G13 -> 0.070925956 | H37: =H13 -> 0.075181513 | I37: =I13 -> 0.079692404 | ... K37: =K13 -> 0.089542385
A38: Savings: MedicaidChurn_Admin (billions) | B38: =B14 -> 3.18 | C38: =C14 -> 3.3708 | D38: =D14 -> 3.573048 | E38: =E14 -> 3.7874309 | F38: =F14 -> 4.0146767 | G38: =G14 -> 4.2555573 | H38: =H14 -> 4.2555573 | I38: =I14 -> 4.2555573 | ... K38: =K14 -> 4.2555573
A39: Savings: Behavioral Savings (billions) | B39: =B24 -> 11.9625 | C39: =C24 -> 12.68025 | D39: =D24 -> 13.441065 | E39: =E24 -> 14.247529 | F39: =F24 -> 15.102381 | G39: =G24 -> 16.008523 | H39: =H24 -> 16.969035 | I39: =I24 -> 17.987177 | ... K39: =K24 -> 20.210392
A41: Total Savings / Revenues (billions) | B41: =SUM(B28:B39) -> 753.1815 | C41: =SUM(C28:C39) -> 713.98839 | D41: =SUM(D28:D39) -> 665.51061 | E41: =SUM(E28:E39) -> 609.75669 | F41: =SUM(F28:F39) -> 592.68405 | G41: =SUM(G28:G39) -> 570.64356 | H41: =SUM(H28:H39) -> 666.87884 | I41: =SUM(I28:I39) -> 772.69424 | ... K41: =SUM(K28:K39) -> 1019.584
A42: Conservative Savings (billions)

Sheet Summary table
B1: 2026 | C1: 2027 | D1: 2028 | E1: 2029 | F1: 2030 | G1: 2031 | H1: 2032 | I1: 2033 | J1: 2034 | K1: 2035
A3: Total Outlays Under Act (Billions) | B3: =Outlays!B20 -> 998.64509 | C3: =Outlays!C20 -> 1046.0277 | D3: =Outlays!D20 -> 1095.8044 | E3: =Outlays!E20 -> 1147.0954 | F3: =Outlays!F20 -> 1203.027 | G3: =Outlays!G20 -> 1261.732 | H3: =Outlays!H20 -> 1323.3499 | I3: =Outlays!I20 -> 1388.0275 | ... K3: =Outlays!K20 -> 1527.1858
A4: Total Savings Under Act (Billions) | B4: =Savings!B41 -> 753.1815 | C4: =Savings!C41 -> 713.98839 | D4: =Savings!D41 -> 665.51061 | E4: =Savings!E41 -> 609.75669 | F4: =Savings!F41 -> 592.68405 | G4: =Savings!G41 -> 570.64356 | H4: =Savings!H41 -> 666.87884 | I4: =Savings!I41 -> 772.69424 | ... K4: =Savings!K41 -> 1019.584
A6: Net Federal Impact = Outlays – Savings (Billions) | B6: =B3 - B4 -> 245.46359 | C6: =C3 - C4 -> 332.03935 | D6: =D3 - D4 -> 430.29381 | E6: =E3 - E4 -> 537.33868 | F6: =F3 - F4 -> 610.34291 | G6: =G3 - G4 -> 691.08839 | H6: =H3 - H4 -> 656.47107 | I6: =I3 - I4 -> 615.33323 | ... K6: =K3 - K4 -> 507.60183
A7: Cumulative Net Impact (Billions) | B7: =B6 -> 245.46359 | C7: =B7 + C6 -> 577.50294 | D7: =C7 + D6 -> 1007.7967 | E7: =D7 + E6 -> 1545.1354 | F7: =E7 + F6 -> 2155.4783 | G7: =F7 + G6 -> 2846.5667 | H7: =G7 + H6 -> 3503.0378 | I7: =H7 + I6 -> 4118.371 | J7: =I7 + J6 -> 4683.8333 | K7: =J7 + K6 -> 5191.4351
A9: 10-Year Net Federal Impact (2026–2035) (Billions) | B9: =SUM(B6:K6) -> 5191.4351

Sheet Consumer Savings
A1: Consumer Impact (billions unless noted)
A2: Year | B2: 2026 | C2: 2027 | D2: 2028 | E2: 2029 | F2: 2030 | G2: 2031 | H2: 2032 | I2: 2033 | J2: 2034 | K2: 2035 | L2: Notes / status
A4: Federal transfers to households
A5: Catastrophic Credits (billions) | B5: 830.08201 | C5: 874.37518 | D5: 921.03184 | E5: 970.1781 | F5: 1021.9468 | G5: 1076.4779 | H5: 1133.9187 | I5: 1194.4247 | J5: 1258.1591 | K5: 1325.2945 | L5: From Outlays: Catastrophic Credits
A6: Federal HSA Deposits (billions) | B6: 279.2 | C6: 290.368 | D6: 301.98272 | E6: 314.06203 | F6: 326.62451 | G6: 339.68949 | H6: 353.27707 | I6: 367.40815 | J6: 382.10448 | K6: 397.38866 | L6: From Outlays: Total Federal HSA Deposits
A7: Total Federal Transfers (Credits + HSA) (billions) | B7: 1109.282 | C7: 1164.7432 | D7: 1223.0146 | E7: 1284.2401 | F7: 1348.5713 | G7: 1416.1674 | H7: 1487.1958 | I7: 1561.8328 | J7: 1640.2636 | K7: 1722.6832
A9: Household catastrophic premium payments (benchmark-based)
A10: Total Benchmark Premium Volume (billions) | B10: 1300 | C10: 1369.368 | D10: 1442.4375 | E10: 1519.4059 | F10: 1600.4814 | G10: 1685.8831 | H10: 1775.8419 | I10: 1870.6008 | J10: 1970.416 | K10: 2075.5574 | L10: From Outlays: Total Benchmark Premium Volume
A11: Average Federal Share of Catastrophic Premium (share, 0–1) | B11: 0.63852462 | C11: 0.63852462 | D11: 0.63852462 | E11: 0.63852462 | F11: 0.63852462 | G11: 0.63852462 | H11: 0.63852462 | I11: 0.63852462 | J11: 0.63852462 | K11: 0.63852462 | L11: From Outlays: Average Federal Share
A12: Household Share of Catastrophic Premium (billions) | B12: 469.91799 | C12: 494.99282 | D12: 521.40563 | E12: 549.22784 | F12: 578.53464 | G12: 609.40524 | H12: 641.92311 | I12: 676.17613 | J12: 712.25688 | K12: 750.26291 | L12: Computed: benchmark volume × (1 − federal share)
A14: Baseline Routine Spend (billions)
A15: HSE Routine Spend (billions)
A16: Routine Savings (billions)
A19: Net household position (partial; transfers minus household catastrophic premium) (billions) | B19: 639.36401 | C19: 669.75036 | D19: 701.60893 | E19: 735.01229 | F19: 770.03668 | G19: 806.76213 | H19: 845.27271 | I19: 885.65668 | J19: 928.00675 | K19: 972.42027 | L19: Computed: (Credits + HSA) − household catastrophic premium
